Traceback (most recent call last):
  File "C:\Python\Python3.12\Lib\site-packages\pandas\core\indexes\base.py", line 3805, in get_loc
    return self._engine.get_loc(casted_key)
           ^^^^^^^^^^^^^^^^^^^^^^^^^^^^^^^^
  File "index.pyx", line 167, in pandas._libs.index.IndexEngine.get_loc
  File "index.pyx", line 196, in pandas._libs.index.IndexEngine.get_loc
  File "pandas\\_libs\\hashtable_class_helper.pxi", line 7081, in pandas._libs.hashtable.PyObjectHashTable.get_item
  File "pandas\\_libs\\hashtable_class_helper.pxi", line 7089, in pandas._libs.hashtable.PyObjectHashTable.get_item
KeyError: 'v_x_1'

The above exception was the direct cause of the following exception:

Traceback (most recent call last):
  File "C:\Python\Python3.12\Lib\site-packages\sklearn\utils\_indexing.py", line 361, in _get_column_indices
    col_idx = all_columns.get_loc(col)
              ^^^^^^^^^^^^^^^^^^^^^^^^
  File "C:\Python\Python3.12\Lib\site-packages\pandas\core\indexes\base.py", line 3812, in get_loc
    raise KeyError(key) from err
KeyError: 'v_x_1'

The above exception was the direct cause of the following exception:

Traceback (most recent call last):
  File "c:\Users\vidcoelh\Documents\Pessoal\AA\task_3_4.py", line 185, in <module>
    best_model, best_rmse, best_degree, best_alpha = validate_poly_regression(entry_train, output_train, entry_val, output_val)
                                                     ^^^^^^^^^^^^^^^^^^^^^^^^^^^^^^^^^^^^^^^^^^^^^^^^^^^^^^^^^^^^^^^^^^^^^^^^^^
  File "c:\Users\vidcoelh\Documents\Pessoal\AA\task_3_4.py", line 163, in validate_poly_regression
    poly_reg_model.fit(X_train, y_train)
  File "C:\Python\Python3.12\Lib\site-packages\sklearn\base.py", line 1473, in wrapper
    return fit_method(estimator, *args, **kwargs)
           ^^^^^^^^^^^^^^^^^^^^^^^^^^^^^^^^^^^^^^
  File "C:\Python\Python3.12\Lib\site-packages\sklearn\pipeline.py", line 469, in fit
    Xt = self._fit(X, y, routed_params)
         ^^^^^^^^^^^^^^^^^^^^^^^^^^^^^^
  File "C:\Python\Python3.12\Lib\site-packages\sklearn\pipeline.py", line 406, in _fit
    X, fitted_transformer = fit_transform_one_cached(
                            ^^^^^^^^^^^^^^^^^^^^^^^^^
  File "C:\Python\Python3.12\Lib\site-packages\joblib\memory.py", line 312, in __call__
    return self.func(*args, **kwargs)
           ^^^^^^^^^^^^^^^^^^^^^^^^^^
  File "C:\Python\Python3.12\Lib\site-packages\sklearn\pipeline.py", line 1310, in _fit_transform_one
    res = transformer.fit_transform(X, y, **params.get("fit_transform", {}))
          ^^^^^^^^^^^^^^^^^^^^^^^^^^^^^^^^^^^^^^^^^^^^^^^^^^^^^^^^^^^^^^^^^^
  File "C:\Python\Python3.12\Lib\site-packages\sklearn\utils\_set_output.py", line 316, in wrapped
    data_to_wrap = f(self, X, *args, **kwargs)
                   ^^^^^^^^^^^^^^^^^^^^^^^^^^^
  File "C:\Python\Python3.12\Lib\site-packages\sklearn\base.py", line 1473, in wrapper
    return fit_method(estimator, *args, **kwargs)
           ^^^^^^^^^^^^^^^^^^^^^^^^^^^^^^^^^^^^^^
  File "C:\Python\Python3.12\Lib\site-packages\sklearn\compose\_column_transformer.py", line 968, in fit_transform
    self._validate_column_callables(X)
  File "C:\Python\Python3.12\Lib\site-packages\sklearn\compose\_column_transformer.py", line 536, in _validate_column_callables
    transformer_to_input_indices[name] = _get_column_indices(X, columns)
                                         ^^^^^^^^^^^^^^^^^^^^^^^^^^^^^^^
  File "C:\Python\Python3.12\Lib\site-packages\sklearn\utils\_indexing.py", line 369, in _get_column_indices
    raise ValueError("A given column is not a column of the dataframe") from e
ValueError: A given column is not a column of the dataframe
