Traceback (most recent call last):
  File "c:\Users\vidcoelh\Documents\Pessoal\AA\task_1.py", line 132, in <module>
    entry_test  = test[features_X]
                  ~~~~^^^^^^^^^^^^
  File "C:\Python\Python3.12\Lib\site-packages\pandas\core\frame.py", line 4108, in __getitem__
    indexer = self.columns._get_indexer_strict(key, "columns")[1]
              ^^^^^^^^^^^^^^^^^^^^^^^^^^^^^^^^^^^^^^^^^^^^^^^^
  File "C:\Python\Python3.12\Lib\site-packages\pandas\core\indexes\base.py", line 6200, in _get_indexer_strict
    self._raise_if_missing(keyarr, indexer, axis_name)
  File "C:\Python\Python3.12\Lib\site-packages\pandas\core\indexes\base.py", line 6252, in _raise_if_missing
    raise KeyError(f"{not_found} not in index")
KeyError: "['rel_x12', 'rel_y12', 'rel_x13', 'rel_y13', 'rel_x32', 'rel_y32', 'd_12', 'd_13', 'd_32', 'inv_d_12', 'inv_d_13', 'inv_d_32', 'v_rel_x12', 'v_rel_y12', 'v_rel_x13', 'v_rel_y13', 'v_rel_x32', 'v_rel_y32', 'speed_1', 'speed_2', 'speed_3', 'v_x_ratio_12', 'v_y_ratio_12', 'v_x_ratio_13', 'v_y_ratio_13', 'v_x_ratio_32', 'v_y_ratio_32'] not in index"
